const {
    ParameterException,
    NotFoundException,
    AuthFailedException,
    ForbiddenException,
    Success,
    HttpException,
} = require("../lib/http-exception");

/**
 * 放在app.use()第一个中间件，可以捕获所有的await next()错误
 * @param ctx
 * @param next
 * @returns {Promise<void>}
 */
const catchError = async (ctx, next) => {
    try {
        await next();
    } catch (e) {
        // 开发环境，直接throw

        const isHttpException = e instanceof HttpException;
        const isDev = global.config.environment === "dev";
        console.error("全局catchError", e.toString());
        if (isDev && !isHttpException) {
            throw e;
        }

        if (isHttpException) {
            ctx.body = {
                msg: e.msg,
                error_code: e.errorCode,
                request: `${ctx.method} ${ctx.path}`,
            };
            ctx.status = e.code;
        } else {
            ctx.body = {
                msg: "未知错误！",
                error_code: 9999,
                request: `${ctx.method} ${ctx.path}`,
            };
            ctx.status = 500;
        }

        // 生产环境，返回错误码以及原因
    }
};

module.exports = catchError;
